Traceback (most recent call last):
  File "/usr/share/miniconda3/envs/hackweek/lib/python3.9/site-packages/jupyter_cache/executors/utils.py", line 51, in single_nb_execution
    executenb(
  File "/usr/share/miniconda3/envs/hackweek/lib/python3.9/site-packages/nbclient/client.py", line 1204, in execute
    return NotebookClient(nb=nb, resources=resources, km=km, **kwargs).execute()
  File "/usr/share/miniconda3/envs/hackweek/lib/python3.9/site-packages/nbclient/util.py", line 84, in wrapped
    return just_run(coro(*args, **kwargs))
  File "/usr/share/miniconda3/envs/hackweek/lib/python3.9/site-packages/nbclient/util.py", line 62, in just_run
    return loop.run_until_complete(coro)
  File "/usr/share/miniconda3/envs/hackweek/lib/python3.9/asyncio/base_events.py", line 642, in run_until_complete
    return future.result()
  File "/usr/share/miniconda3/envs/hackweek/lib/python3.9/site-packages/nbclient/client.py", line 663, in async_execute
    await self.async_execute_cell(
  File "/usr/share/miniconda3/envs/hackweek/lib/python3.9/site-packages/nbclient/client.py", line 965, in async_execute_cell
    await self._check_raise_for_error(cell, cell_index, exec_reply)
  File "/usr/share/miniconda3/envs/hackweek/lib/python3.9/site-packages/nbclient/client.py", line 862, in _check_raise_for_error
    raise CellExecutionError.from_cell_and_msg(cell, exec_reply_content)
nbclient.exceptions.CellExecutionError: An error occurred while executing the following cell:
------------------
# Set Earthdata credentials
uid = 'zhfair'
email = 'zhfair@umich.edu'
region.earthdata_login(uid, email)

# Order the granules
region.order_granules()
------------------

[0;31m---------------------------------------------------------------------------[0m
[0;31mFileNotFoundError[0m                         Traceback (most recent call last)
File [0;32m/usr/share/miniconda3/envs/hackweek/lib/python3.9/site-packages/icepyx/core/Earthdata.py:131[0m, in [0;36mEarthdata.login[0;34m(self, attempts)[0m
[1;32m    130[0m url [38;5;241m=[39m [38;5;124m"[39m[38;5;124murs.earthdata.nasa.gov[39m[38;5;124m"[39m
[0;32m--> 131[0m [38;5;28mself[39m[38;5;241m.[39muid, _, [38;5;28mself[39m[38;5;241m.[39mpswd [38;5;241m=[39m [43mnetrc[49m[38;5;241;43m.[39;49m[43mnetrc[49m[43m([49m[38;5;28;43mself[39;49m[38;5;241;43m.[39;49m[43mnetrc[49m[43m)[49m[38;5;241m.[39mauthenticators(url)
[1;32m    132[0m session [38;5;241m=[39m [38;5;28mself[39m[38;5;241m.[39m_start_session()

File [0;32m/usr/share/miniconda3/envs/hackweek/lib/python3.9/netrc.py:29[0m, in [0;36mnetrc.__init__[0;34m(self, file)[0m
[1;32m     28[0m [38;5;28mself[39m[38;5;241m.[39mmacros [38;5;241m=[39m {}
[0;32m---> 29[0m [38;5;28;01mwith[39;00m [38;5;28;43mopen[39;49m[43m([49m[43mfile[49m[43m)[49m [38;5;28;01mas[39;00m fp:
[1;32m     30[0m     [38;5;28mself[39m[38;5;241m.[39m_parse(file, fp, default_netrc)

[0;31mFileNotFoundError[0m: [Errno 2] No such file or directory: '/home/runner/.netrc'

During handling of the above exception, another exception occurred:

[0;31mStdinNotImplementedError[0m                  Traceback (most recent call last)
Input [0;32mIn [11][0m, in [0;36m<cell line: 4>[0;34m()[0m
[1;32m      2[0m uid [38;5;241m=[39m [38;5;124m'[39m[38;5;124mzhfair[39m[38;5;124m'[39m
[1;32m      3[0m email [38;5;241m=[39m [38;5;124m'[39m[38;5;124mzhfair@umich.edu[39m[38;5;124m'[39m
[0;32m----> 4[0m [43mregion[49m[38;5;241;43m.[39;49m[43mearthdata_login[49m[43m([49m[43muid[49m[43m,[49m[43m [49m[43memail[49m[43m)[49m
[1;32m      6[0m [38;5;66;03m# Order the granules[39;00m
[1;32m      7[0m region[38;5;241m.[39morder_granules()

File [0;32m/usr/share/miniconda3/envs/hackweek/lib/python3.9/site-packages/icepyx/core/query.py:851[0m, in [0;36mQuery.earthdata_login[0;34m(self, uid, email, s3token)[0m
[1;32m    846[0m     [38;5;28;01massert[39;00m (
[1;32m    847[0m         is_ec2() [38;5;241m==[39m [38;5;28;01mTrue[39;00m
[1;32m    848[0m     ), [38;5;124m"[39m[38;5;124mYou must be working from a valid AWS instance to use s3 data access[39m[38;5;124m"[39m
[1;32m    849[0m     capability_url [38;5;241m=[39m [38;5;124m"[39m[38;5;124mhttps://data.nsidc.earthdatacloud.nasa.gov/s3credentials[39m[38;5;124m"[39m
[0;32m--> 851[0m [38;5;28mself[39m[38;5;241m.[39m_session [38;5;241m=[39m [43mEarthdata[49m[43m([49m[43muid[49m[43m,[49m[43m [49m[43memail[49m[43m,[49m[43m [49m[43mcapability_url[49m[43m)[49m[38;5;241;43m.[39;49m[43mlogin[49m[43m([49m[43m)[49m
[1;32m    853[0m [38;5;66;03m# DevNote: might make sense to do this part elsewhere in the future, but wanted to get it implemented for now[39;00m
[1;32m    854[0m [38;5;28;01mif[39;00m s3token [38;5;241m==[39m [38;5;28;01mTrue[39;00m:

File [0;32m/usr/share/miniconda3/envs/hackweek/lib/python3.9/site-packages/icepyx/core/Earthdata.py:137[0m, in [0;36mEarthdata.login[0;34m(self, attempts)[0m
[1;32m    134[0m [38;5;28;01mexcept[39;00m:
[1;32m    135[0m     [38;5;66;03m# if not using an environmental variable for password[39;00m
[1;32m    136[0m     [38;5;28;01mif[39;00m [38;5;129;01mnot[39;00m [38;5;28mself[39m[38;5;241m.[39mpswd:
[0;32m--> 137[0m         [38;5;28mself[39m[38;5;241m.[39mpswd [38;5;241m=[39m [43mgetpass[49m[38;5;241;43m.[39;49m[43mgetpass[49m[43m([49m[38;5;124;43m"[39;49m[38;5;124;43mEarthdata Login password: [39;49m[38;5;124;43m"[39;49m[43m)[49m
[1;32m    138[0m     [38;5;28;01mfor[39;00m i [38;5;129;01min[39;00m [38;5;28mrange[39m(attempts):
[1;32m    139[0m         [38;5;28;01mtry[39;00m:

File [0;32m/usr/share/miniconda3/envs/hackweek/lib/python3.9/site-packages/ipykernel/kernelbase.py:1047[0m, in [0;36mKernel.getpass[0;34m(self, prompt, stream)[0m
[1;32m   1040[0m [38;5;124;03m"""Forward getpass to frontends[39;00m
[1;32m   1041[0m 
[1;32m   1042[0m [38;5;124;03mRaises[39;00m
[1;32m   1043[0m [38;5;124;03m------[39;00m
[1;32m   1044[0m [38;5;124;03mStdinNotImplementedError if active frontend doesn't support stdin.[39;00m
[1;32m   1045[0m [38;5;124;03m"""[39;00m
[1;32m   1046[0m [38;5;28;01mif[39;00m [38;5;129;01mnot[39;00m [38;5;28mself[39m[38;5;241m.[39m_allow_stdin:
[0;32m-> 1047[0m     [38;5;28;01mraise[39;00m StdinNotImplementedError(
[1;32m   1048[0m         [38;5;124m"[39m[38;5;124mgetpass was called, but this frontend does not support input requests.[39m[38;5;124m"[39m
[1;32m   1049[0m     )
[1;32m   1050[0m [38;5;28;01mif[39;00m stream [38;5;129;01mis[39;00m [38;5;129;01mnot[39;00m [38;5;28;01mNone[39;00m:
[1;32m   1051[0m     [38;5;28;01mimport[39;00m [38;5;21;01mwarnings[39;00m

[0;31mStdinNotImplementedError[0m: getpass was called, but this frontend does not support input requests.
StdinNotImplementedError: getpass was called, but this frontend does not support input requests.

